Workbook

Sheet clinical_study
A1: subject_id | B1: age | C1: sex | D1: weight | E1: height | F1: trt_grp | G1: RESPONSE | H1: BMI | I1: protein_concentration | J1: response_label
A2: SUBJ_001 | B2: 46 | C2: Female | D2: 84.66 | E2: 1.59 | F2: DRUG | G2: N | H2: =(D2)/(E2^2) -> 33.487599 | I2: {=XLOOKUP(A2,protein_data!A:A,protein_data!B:B,"")} -> 148 | J2: =if(G2="y","Responder","Non-Responder") -> Non-Responder
A3: SUBJ_002 | B3: 47 | C3: Female | D3: 71.21 | E3: 1.64 | F3: DRUG | G3: Y | H3: =(D3)/(E3^2) -> 26.476056 | I3: {=XLOOKUP(A3,protein_data!A:A,protein_data!B:B,"")} -> 85 | J3: =if(G3="y","Responder","Non-Responder") -> Responder
A4: SUBJ_003 | B4: 48 | C4: Female | D4: 69.85 | E4: 1.73 | F4: CONTROL | G4: N | H4: =(D4)/(E4^2) -> 23.338568 | I4: {=XLOOKUP(A4,protein_data!A:A,protein_data!B:B,"")} -> 183 | J4: =if(G4="y","Responder","Non-Responder") -> Non-Responder
A5: SUBJ_004 | B5: 59 | C5: Female | D5: 62.94 | E5: 1.5 | F5: DRUG | G5: Y | H5: =(D5)/(E5^2) -> 27.973333 | I5: {=XLOOKUP(A5,protein_data!A:A,protein_data!B:B,"")} -> 89 | J5: =if(G5="y","Responder","Non-Responder") -> Responder
A6: SUBJ_005 | B6: 59 | C6: Female | D6: 113.91 | E6: 1.63 | F6: CONTROL | G6: N | H6: =(D6)/(E6^2) -> 42.873273 | I6: {=XLOOKUP(A6,protein_data!A:A,protein_data!B:B,"")} -> 137 | J6: =if(G6="y","Responder","Non-Responder") -> Non-Responder
A7: SUBJ_006 | B7: 63 | C7: Male | D7: 79.33 | E7: 1.77 | F7: CONTROL | G7: Y | H7: =(D7)/(E7^2) -> 25.321587 | I7: {=XLOOKUP(A7,protein_data!A:A,protein_data!B:B,"")} -> 116 | J7: =if(G7="y","Responder","Non-Responder") -> Responder
A8: SUBJ_007 | B8: 77 | C8: Male | D8: 96.12 | E8: 1.77 | F8: CONTROL | G8: N | H8: =(D8)/(E8^2) -> 30.680839 | I8: {=XLOOKUP(A8,protein_data!A:A,protein_data!B:B,"")} -> 78 | J8: =if(G8="y","Responder","Non-Responder") -> Non-Responder
A9: SUBJ_008 | B9: 57 | C9: Male | D9: 93.5 | E9: 1.63 | F9: DRUG | G9: N | H9: =(D9)/(E9^2) -> 35.191388 | I9: {=XLOOKUP(A9,protein_data!A:A,protein_data!B:B,"")} -> 115 | J9: =if(G9="y","Responder","Non-Responder") -> Non-Responder
A10: SUBJ_009 | B10: 72 | C10: Male | D10: 85.57 | E10: 1.68 | F10: DRUG | G10: N | H10: =(D10)/(E10^2) -> 30.318169 | I10: {=XLOOKUP(A10,protein_data!A:A,protein_data!B:B,"")} -> 197 | J10: =if(G10="y","Responder","Non-Responder") -> Non-Responder
A11: SUBJ_010 | B11: 73 | C11: Female | D11: NA | E11: 1.64 | F11: DRUG | G11: Y
A12: SUBJ_011 | B12: 67 | C12: Male | D12: 109.12 | E12: 1.71 | F12: CONTROL | G12: Y | H12: =(D12)/(E12^2) -> 37.317465 | I12: {=XLOOKUP(A12,protein_data!A:A,protein_data!B:B,"")} -> 110 | J12: =if(G12="y","Responder","Non-Responder") -> Responder
A13: SUBJ_012 | B13: 53 | C13: Male | D13: 125.02 | E13: 1.82 | F13: DRUG | G13: N | H13: =(D13)/(E13^2) -> 37.743026 | I13: {=XLOOKUP(A13,protein_data!A:A,protein_data!B:B,"")} -> 168 | J13: =if(G13="y","Responder","Non-Responder") -> Non-Responder
A14: SUBJ_013 | B14: 58 | C14: Female | D14: 76.31 | E14: 1.68 | F14: DRUG | G14: N | H14: =(D14)/(E14^2) -> 27.037273 | I14: {=XLOOKUP(A14,protein_data!A:A,protein_data!B:B,"")} -> 139 | J14: =if(G14="y","Responder","Non-Responder") -> Non-Responder
A15: SUBJ_014 | B15: 55 | C15: Male | D15: 90.99 | E15: 1.75 | F15: DRUG | G15: N | H15: =(D15)/(E15^2) -> 29.71102 | I15: {=XLOOKUP(A15,protein_data!A:A,protein_data!B:B,"")} -> 189 | J15: =if(G15="y","Responder","Non-Responder") -> Non-Responder
A16: SUBJ_015 | B16: 65 | C16: Male | D16: 80.21 | E16: 1.77 | F16: DRUG | G16: N | H16: =(D16)/(E16^2) -> 25.602477 | I16: {=XLOOKUP(A16,protein_data!A:A,protein_data!B:B,"")} -> 166 | J16: =if(G16="y","Responder","Non-Responder") -> Non-Responder
A17: SUBJ_016 | B17: 54 | C17: Male | D17: 86.75 | E17: 1.71 | F17: DRUG | G17: Y | H17: =(D17)/(E17^2) -> 29.667248 | I17: {=XLOOKUP(A17,protein_data!A:A,protein_data!B:B,"")} -> 100 | J17: =if(G17="y","Responder","Non-Responder") -> Responder
A18: SUBJ_017 | B18: 57 | C18: Male | D18: 144.15 | E18: 1.78 | F18: CONTROL | G18: N | H18: =(D18)/(E18^2) -> 45.496149 | I18: {=XLOOKUP(A18,protein_data!A:A,protein_data!B:B,"")} -> 118 | J18: =if(G18="y","Responder","Non-Responder") -> Non-Responder
A19: SUBJ_018 | B19: 65 | C19: Female | D19: 80.04 | E19: 1.64 | F19: CONTROL | G19: Y | H19: =(D19)/(E19^2) -> 29.759072 | I19: {=XLOOKUP(A19,protein_data!A:A,protein_data!B:B,"")} -> 107 | J19: =if(G19="y","Responder","Non-Responder") -> Responder
A20: SUBJ_019 | B20: 51 | C20: Male | D20: 131.63 | E20: 1.75 | F20: DRUG | G20: Y | H20: =(D20)/(E20^2) -> 42.981224 | I20: {=XLOOKUP(A20,protein_data!A:A,protein_data!B:B,"")} -> 103 | J20: =if(G20="y","Responder","Non-Responder") -> Responder
A21: SUBJ_020 | B21: 73 | C21: Female | D21: 94.38 | E21: 1.65 | F21: DRUG | G21: Y | H21: =(D21)/(E21^2) -> 34.666667 | I21: {=XLOOKUP(A21,protein_data!A:A,protein_data!B:B,"")} -> 115 | J21: =if(G21="y","Responder","Non-Responder") -> Responder
A22: SUBJ_021 | B22: 61 | C22: Male | D22: 122.87 | E22: 1.78 | F22: CONTROL | G22: N | H22: =(D22)/(E22^2) -> 38.779826 | I22: {=XLOOKUP(A22,protein_data!A:A,protein_data!B:B,"")} -> 126 | J22: =if(G22="y","Responder","Non-Responder") -> Non-Responder
A23: SUBJ_022 | B23: 55 | C23: Female | D23: 85.69 | E23: 1.56 | F23: DRUG | G23: N | H23: =(D23)/(E23^2) -> 35.21121 | I23: {=XLOOKUP(A23,protein_data!A:A,protein_data!B:B,"")} -> 99 | J23: =if(G23="y","Responder","Non-Responder") -> Non-Responder
... A50: SUBJ_049 | B50: 63 | C50: Female | D50: 104.13 | E50: 1.63 | F50: DRUG | G50: Y | H50: =(D50)/(E50^2) -> 39.192292 | I50: {=XLOOKUP(A50,protein_data!A:A,protein_data!B:B,"")} -> 103 | J50: =if(G50="y","Responder","Non-Responder") -> Responder
A51: SUBJ_050 | B51: 65 | C51: Male | D51: NA | E51: 1.71 | F51: DRUG | G51: N
A52: SUBJ_051 | B52: 59 | C52: Female | D52: 48.9 | E52: 1.59 | F52: DRUG | G52: N | H52: =(D52)/(E52^2) -> 19.342589 | I52: {=XLOOKUP(A52,protein_data!A:A,protein_data!B:B,"")} -> 103 | J52: =if(G52="y","Responder","Non-Responder") -> Non-Responder
A53: SUBJ_052 | B53: 51 | C53: Female | D53: 63.17 | E53: 1.62 | F53: DRUG | G53: Y | H53: =(D53)/(E53^2) -> 24.070264 | I53: {=XLOOKUP(A53,protein_data!A:A,protein_data!B:B,"")} -> 101 | J53: =if(G53="y","Responder","Non-Responder") -> Responder
A54: SUBJ_053 | B54: 65 | C54: Male | D54: 64.84 | E54: 1.64 | F54: CONTROL | G54: Y | H54: =(D54)/(E54^2) -> 24.107674 | I54: {=XLOOKUP(A54,protein_data!A:A,protein_data!B:B,"")} -> 88 | J54: =if(G54="y","Responder","Non-Responder") -> Responder
A55: SUBJ_054 | B55: 58 | C55: Female | D55: 88.23 | E55: 1.62 | F55: CONTROL | G55: N | H55: =(D55)/(E55^2) -> 33.619113 | I55: {=XLOOKUP(A55,protein_data!A:A,protein_data!B:B,"")} -> 176 | J55: =if(G55="y","Responder","Non-Responder") -> Non-Responder
A56: SUBJ_055 | B56: 70 | C56: Female | D56: 82.39 | E56: 1.54 | F56: CONTROL | G56: N | H56: =(D56)/(E56^2) -> 34.74026 | I56: {=XLOOKUP(A56,protein_data!A:A,protein_data!B:B,"")} -> 150 | J56: =if(G56="y","Responder","Non-Responder") -> Non-Responder
A57: SUBJ_056 | B57: 64 | C57: Female | D57: 57.12 | E57: 1.58 | F57: CONTROL | G57: N | H57: =(D57)/(E57^2) -> 22.880949 | I57: {=XLOOKUP(A57,protein_data!A:A,protein_data!B:B,"")} -> 73 | J57: =if(G57="y","Responder","Non-Responder") -> Non-Responder
A58: SUBJ_057 | B58: 57 | C58: Male | D58: 104.77 | E58: 1.67 | F58: DRUG | G58: N | H58: =(D58)/(E58^2) -> 37.566783 | I58: {=XLOOKUP(A58,protein_data!A:A,protein_data!B:B,"")} -> 187 | J58: =if(G58="y","Responder","Non-Responder") -> Non-Responder
A59: SUBJ_058 | B59: 73 | C59: Male | D59: 147.54 | E59: 1.78 | F59: DRUG | G59: Y | H59: =(D59)/(E59^2) -> 46.56609 | I59: {=XLOOKUP(A59,protein_data!A:A,protein_data!B:B,"")} -> 100 | J59: =if(G59="y","Responder","Non-Responder") -> Responder
A60: SUBJ_059 | B60: 58 | C60: Male | D60: 137.81 | E60: 1.85 | F60: DRUG | G60: Y | H60: =(D60)/(E60^2) -> 40.265888 | I60: {=XLOOKUP(A60,protein_data!A:A,protein_data!B:B,"")} -> 146 | J60: =if(G60="y","Responder","Non-Responder") -> Responder
A61: SUBJ_060 | B61: 59 | C61: Female | D61: 109.88 | E61: 1.63 | F61: CONTROL | G61: N | H61: =(D61)/(E61^2) -> 41.356468 | I61: {=XLOOKUP(A61,protein_data!A:A,protein_data!B:B,"")} -> 105 | J61: =if(G61="y","Responder","Non-Responder") -> Non-Responder
A62: SUBJ_061 | B62: 61 | C62: Male | D62: NA | E62: 1.79 | F62: CONTROL | G62: N
A63: SUBJ_062 | B63: 63 | C63: Male | D63: 97.35 | E63: 1.73 | F63: DRUG | G63: N | H63: =(D63)/(E63^2) -> 32.526981 | I63: {=XLOOKUP(A63,protein_data!A:A,protein_data!B:B,"")} -> 133 | J63: =if(G63="y","Responder","Non-Responder") -> Non-Responder
A64: SUBJ_063 | B64: 52 | C64: Male | D64: 77.23 | E64: 1.76 | F64: CONTROL | G64: Y | H64: =(D64)/(E64^2) -> 24.932206 | I64: {=XLOOKUP(A64,protein_data!A:A,protein_data!B:B,"")} -> 44 | J64: =if(G64="y","Responder","Non-Responder") -> Responder
A65: SUBJ_064 | B65: 69 | C65: Male | D65: 76.46 | E65: 1.74 | F65: CONTROL | G65: N | H65: =(D65)/(E65^2) -> 25.254327 | I65: {=XLOOKUP(A65,protein_data!A:A,protein_data!B:B,"")} -> 141 | J65: =if(G65="y","Responder","Non-Responder") -> Non-Responder
A66: SUBJ_065 | B66: 59 | C66: Female | D66: 81.74 | E66: 1.58 | F66: CONTROL | G66: N | H66: =(D66)/(E66^2) -> 32.74315 | I66: {=XLOOKUP(A66,protein_data!A:A,protein_data!B:B,"")} -> 114 | J66: =if(G66="y","Responder","Non-Responder") -> Non-Responder
...

Sheet response_vs_proteinconcentratio

Sheet response_vs_bmi_pivot

Sheet response_vs_age_pivot

Sheet Detail1
A1: subject_id | B1: age | C1: sex | D1: weight | E1: height | F1: trt_grp | G1: RESPONSE | H1: BMI | I1: protein_concentration | J1: response_label
A2: SUBJ_010 | B2: 73 | C2: Female | D2: NA | E2: 1.64 | F2: DRUG | G2: Y
A3: SUBJ_050 | B3: 65 | C3: Male | D3: NA | E3: 1.71 | F3: DRUG | G3: N
A4: SUBJ_061 | B4: 61 | C4: Male | D4: NA | E4: 1.79 | F4: CONTROL | G4: N
A5: SUBJ_082 | B5: 65 | C5: Male | D5: NA | E5: 1.78 | F5: CONTROL | G5: N
A6: SUBJ_146 | B6: 56 | C6: Female | D6: NA | E6: 1.57 | F6: CONTROL | G6: N
A7: SUBJ_372 | B7: 67 | C7: Female | D7: NA | E7: 1.62 | F7: CONTROL | G7: N
A8: SUBJ_427 | B8: 66 | C8: Male | D8: NA | E8: 1.83 | F8: CONTROL | G8: N
A9: SUBJ_495 | B9: 60 | C9: Female | D9: NA | E9: 1.65 | F9: CONTROL | G9: N
A10: SUBJ_523 | B10: 62 | C10: Female | D10: NA | E10: 1.6 | F10: DRUG | G10: N
A11: SUBJ_685 | B11: 74 | C11: Male | D11: NA | E11: 1.81 | F11: CONTROL | G11: N
A12: SUBJ_707 | B12: 72 | C12: Male | D12: NA | E12: 1.75 | F12: DRUG | G12: Y
A13: SUBJ_A69 | B13: 7.2 | C13: Female | D13: 22.31 | E13: 1.193 | F13: DRUG | G13: N
A14: SUBJ_A70 | B14: 8.31 | C14: Female | D14: 24.22 | E14: 1.2744 | F14: CONTROL | G14: N
A15: SUBJ_A71 | B15: 7.854 | C15: Male | D15: 23.176 | E15: 1.26343 | F15: CONTROL | G15: N

Sheet trt_grp_vs_response_label_pivot

Sheet protein_data
A1: participant_id | B1: protein_concentration
A2: SUBJ_001 | B2: 148
A3: SUBJ_002 | B3: 85
A4: SUBJ_003 | B4: 183
A5: SUBJ_004 | B5: 89
A6: SUBJ_005 | B6: 137
A7: SUBJ_006 | B7: 116
A8: SUBJ_007 | B8: 78
A9: SUBJ_008 | B9: 115
A10: SUBJ_009 | B10: 197
A11: SUBJ_010 | B11: 125
A12: SUBJ_011 | B12: 110
A13: SUBJ_012 | B13: 168
... A76: SUBJ_075 | B76: 79
A77: SUBJ_076 | B77: NA
A78: SUBJ_077 | B78: 62
A79: SUBJ_078 | B79: 95
A80: SUBJ_079 | B80: 131
A81: SUBJ_080 | B81: 112
A82: SUBJ_081 | B82: 113
A83: SUBJ_082 | B83: 74
A84: SUBJ_083 | B84: 83
A85: SUBJ_084 | B85: 101
A86: SUBJ_085 | B86: 137
A87: SUBJ_086 | B87: 110
A88: SUBJ_087 | B88: 106
A89: SUBJ_088 | B89: 100
... A183: SUBJ_182 | B183: 119
A184: SUBJ_183 | B184: NA
A185: SUBJ_184 | B185: 73
A186: SUBJ_185 | B186: 141
A187: SUBJ_186 | B187: 194
A188: SUBJ_187 | B188: 181
A189: SUBJ_188 | B189: 128
A190: SUBJ_189 | B190: 109
A191: SUBJ_190 | B191: 139
A192: SUBJ_191 | B192: 111
A193: SUBJ_192 | B193: 123
A194: SUBJ_193 | B194: 159
A195: SUBJ_194 | B195: 135
...
